2021-04-11 03:48:57,442 Exception during reset or similar
Traceback (most recent call last):
  File "E:\Upwork\2020\gmail_app\gmail_app\env\lib\site-packages\sqlalchemy\pool\base.py", line 670, in _finalize_fairy
    fairy._reset(pool)
  File "E:\Upwork\2020\gmail_app\gmail_app\env\lib\site-packages\sqlalchemy\pool\base.py", line 875, in _reset
    pool._dialect.do_rollback(self)
  File "E:\Upwork\2020\gmail_app\gmail_app\env\lib\site-packages\sqlalchemy\engine\default.py", line 631, in do_rollback
    dbapi_connection.rollback()
sqlite3.ProgrammingError: SQLite objects created in a thread can only be used in that same thread. The object was created in thread id 14996 and this is thread id 14448.
2021-04-11 03:48:57,445 Exception closing connection <sqlite3.Connection object at 0x000002DDDC667E30>
Traceback (most recent call last):
  File "E:\Upwork\2020\gmail_app\gmail_app\env\lib\site-packages\sqlalchemy\pool\base.py", line 670, in _finalize_fairy
    fairy._reset(pool)
  File "E:\Upwork\2020\gmail_app\gmail_app\env\lib\site-packages\sqlalchemy\pool\base.py", line 875, in _reset
    pool._dialect.do_rollback(self)
  File "E:\Upwork\2020\gmail_app\gmail_app\env\lib\site-packages\sqlalchemy\engine\default.py", line 631, in do_rollback
    dbapi_connection.rollback()
sqlite3.ProgrammingError: SQLite objects created in a thread can only be used in that same thread. The object was created in thread id 14996 and this is thread id 14448.

During handling of the above exception, another exception occurred:

Traceback (most recent call last):
  File "E:\Upwork\2020\gmail_app\gmail_app\env\lib\site-packages\sqlalchemy\pool\base.py", line 238, in _close_connection
    self._dialect.do_close(connection)
  File "E:\Upwork\2020\gmail_app\gmail_app\env\lib\site-packages\sqlalchemy\engine\default.py", line 637, in do_close
    dbapi_connection.close()
sqlite3.ProgrammingError: SQLite objects created in a thread can only be used in that same thread. The object was created in thread id 14996 and this is thread id 14448.
2021-04-11 03:48:57,446 Exception during reset or similar
Traceback (most recent call last):
  File "E:\Upwork\2020\gmail_app\gmail_app\env\lib\site-packages\sqlalchemy\pool\base.py", line 670, in _finalize_fairy
    fairy._reset(pool)
  File "E:\Upwork\2020\gmail_app\gmail_app\env\lib\site-packages\sqlalchemy\pool\base.py", line 875, in _reset
    pool._dialect.do_rollback(self)
  File "E:\Upwork\2020\gmail_app\gmail_app\env\lib\site-packages\sqlalchemy\engine\default.py", line 631, in do_rollback
    dbapi_connection.rollback()
sqlite3.ProgrammingError: SQLite objects created in a thread can only be used in that same thread. The object was created in thread id 14996 and this is thread id 14448.
2021-04-11 03:48:57,446 Exception closing connection <sqlite3.Connection object at 0x000002DDDC6DE1F0>
Traceback (most recent call last):
  File "E:\Upwork\2020\gmail_app\gmail_app\env\lib\site-packages\sqlalchemy\pool\base.py", line 670, in _finalize_fairy
    fairy._reset(pool)
  File "E:\Upwork\2020\gmail_app\gmail_app\env\lib\site-packages\sqlalchemy\pool\base.py", line 875, in _reset
    pool._dialect.do_rollback(self)
  File "E:\Upwork\2020\gmail_app\gmail_app\env\lib\site-packages\sqlalchemy\engine\default.py", line 631, in do_rollback
    dbapi_connection.rollback()
sqlite3.ProgrammingError: SQLite objects created in a thread can only be used in that same thread. The object was created in thread id 14996 and this is thread id 14448.

During handling of the above exception, another exception occurred:

Traceback (most recent call last):
  File "E:\Upwork\2020\gmail_app\gmail_app\env\lib\site-packages\sqlalchemy\pool\base.py", line 238, in _close_connection
    self._dialect.do_close(connection)
  File "E:\Upwork\2020\gmail_app\gmail_app\env\lib\site-packages\sqlalchemy\engine\default.py", line 637, in do_close
    dbapi_connection.close()
sqlite3.ProgrammingError: SQLite objects created in a thread can only be used in that same thread. The object was created in thread id 14996 and this is thread id 14448.
2021-04-11 21:23:15,868 Error at downloading email - fasteners360@gmail.com - Error connecting to SOCKS5 proxy 81.28.96.172:60742: [WinError 10061] No connection could be made because the target machine actively refused it
2021-04-11 21:25:03,287 Exception during reset or similar
Traceback (most recent call last):
  File "E:\Upwork\2020\gmail_app\gmail_app\env\lib\site-packages\sqlalchemy\pool\base.py", line 670, in _finalize_fairy
    fairy._reset(pool)
  File "E:\Upwork\2020\gmail_app\gmail_app\env\lib\site-packages\sqlalchemy\pool\base.py", line 875, in _reset
    pool._dialect.do_rollback(self)
  File "E:\Upwork\2020\gmail_app\gmail_app\env\lib\site-packages\sqlalchemy\engine\default.py", line 631, in do_rollback
    dbapi_connection.rollback()
sqlite3.ProgrammingError: SQLite objects created in a thread can only be used in that same thread. The object was created in thread id 12648 and this is thread id 6388.
2021-04-11 21:25:03,322 Exception closing connection <sqlite3.Connection object at 0x0000022F7FF0E110>
Traceback (most recent call last):
  File "E:\Upwork\2020\gmail_app\gmail_app\env\lib\site-packages\sqlalchemy\pool\base.py", line 670, in _finalize_fairy
    fairy._reset(pool)
  File "E:\Upwork\2020\gmail_app\gmail_app\env\lib\site-packages\sqlalchemy\pool\base.py", line 875, in _reset
    pool._dialect.do_rollback(self)
  File "E:\Upwork\2020\gmail_app\gmail_app\env\lib\site-packages\sqlalchemy\engine\default.py", line 631, in do_rollback
    dbapi_connection.rollback()
sqlite3.ProgrammingError: SQLite objects created in a thread can only be used in that same thread. The object was created in thread id 12648 and this is thread id 6388.

During handling of the above exception, another exception occurred:

Traceback (most recent call last):
  File "E:\Upwork\2020\gmail_app\gmail_app\env\lib\site-packages\sqlalchemy\pool\base.py", line 238, in _close_connection
    self._dialect.do_close(connection)
  File "E:\Upwork\2020\gmail_app\gmail_app\env\lib\site-packages\sqlalchemy\engine\default.py", line 637, in do_close
    dbapi_connection.close()
sqlite3.ProgrammingError: SQLite objects created in a thread can only be used in that same thread. The object was created in thread id 12648 and this is thread id 6388.
2021-04-11 22:17:14,175 Exception during reset or similar
Traceback (most recent call last):
  File "E:\Upwork\2020\gmail_app\gmail_app\env\lib\site-packages\sqlalchemy\pool\base.py", line 670, in _finalize_fairy
    fairy._reset(pool)
  File "E:\Upwork\2020\gmail_app\gmail_app\env\lib\site-packages\sqlalchemy\pool\base.py", line 875, in _reset
    pool._dialect.do_rollback(self)
  File "E:\Upwork\2020\gmail_app\gmail_app\env\lib\site-packages\sqlalchemy\engine\default.py", line 631, in do_rollback
    dbapi_connection.rollback()
sqlite3.ProgrammingError: SQLite objects created in a thread can only be used in that same thread. The object was created in thread id 12648 and this is thread id 6388.
2021-04-11 22:17:14,176 Exception closing connection <sqlite3.Connection object at 0x0000022F7FE96D50>
Traceback (most recent call last):
  File "E:\Upwork\2020\gmail_app\gmail_app\env\lib\site-packages\sqlalchemy\pool\base.py", line 670, in _finalize_fairy
    fairy._reset(pool)
  File "E:\Upwork\2020\gmail_app\gmail_app\env\lib\site-packages\sqlalchemy\pool\base.py", line 875, in _reset
    pool._dialect.do_rollback(self)
  File "E:\Upwork\2020\gmail_app\gmail_app\env\lib\site-packages\sqlalchemy\engine\default.py", line 631, in do_rollback
    dbapi_connection.rollback()
sqlite3.ProgrammingError: SQLite objects created in a thread can only be used in that same thread. The object was created in thread id 12648 and this is thread id 6388.

During handling of the above exception, another exception occurred:

Traceback (most recent call last):
  File "E:\Upwork\2020\gmail_app\gmail_app\env\lib\site-packages\sqlalchemy\pool\base.py", line 238, in _close_connection
    self._dialect.do_close(connection)
  File "E:\Upwork\2020\gmail_app\gmail_app\env\lib\site-packages\sqlalchemy\engine\default.py", line 637, in do_close
    dbapi_connection.close()
sqlite3.ProgrammingError: SQLite objects created in a thread can only be used in that same thread. The object was created in thread id 12648 and this is thread id 6388.
2021-04-11 22:17:30,400 Error at downloading email - fasteners360@gmail.com - Error connecting to SOCKS5 proxy 81.28.96.172:60742: [WinError 10061] No connection could be made because the target machine actively refused it
2021-04-11 22:20:21,357 Exception during reset or similar
Traceback (most recent call last):
  File "E:\Upwork\2020\gmail_app\gmail_app\env\lib\site-packages\sqlalchemy\pool\base.py", line 670, in _finalize_fairy
    fairy._reset(pool)
  File "E:\Upwork\2020\gmail_app\gmail_app\env\lib\site-packages\sqlalchemy\pool\base.py", line 875, in _reset
    pool._dialect.do_rollback(self)
  File "E:\Upwork\2020\gmail_app\gmail_app\env\lib\site-packages\sqlalchemy\engine\default.py", line 631, in do_rollback
    dbapi_connection.rollback()
sqlite3.ProgrammingError: SQLite objects created in a thread can only be used in that same thread. The object was created in thread id 11424 and this is thread id 3080.
2021-04-11 22:20:21,383 Exception closing connection <sqlite3.Connection object at 0x000001F35C416B90>
Traceback (most recent call last):
  File "E:\Upwork\2020\gmail_app\gmail_app\env\lib\site-packages\sqlalchemy\pool\base.py", line 670, in _finalize_fairy
    fairy._reset(pool)
  File "E:\Upwork\2020\gmail_app\gmail_app\env\lib\site-packages\sqlalchemy\pool\base.py", line 875, in _reset
    pool._dialect.do_rollback(self)
  File "E:\Upwork\2020\gmail_app\gmail_app\env\lib\site-packages\sqlalchemy\engine\default.py", line 631, in do_rollback
    dbapi_connection.rollback()
sqlite3.ProgrammingError: SQLite objects created in a thread can only be used in that same thread. The object was created in thread id 11424 and this is thread id 3080.

During handling of the above exception, another exception occurred:

Traceback (most recent call last):
  File "E:\Upwork\2020\gmail_app\gmail_app\env\lib\site-packages\sqlalchemy\pool\base.py", line 238, in _close_connection
    self._dialect.do_close(connection)
  File "E:\Upwork\2020\gmail_app\gmail_app\env\lib\site-packages\sqlalchemy\engine\default.py", line 637, in do_close
    dbapi_connection.close()
sqlite3.ProgrammingError: SQLite objects created in a thread can only be used in that same thread. The object was created in thread id 11424 and this is thread id 3080.
2021-04-11 22:20:21,384 Exception during reset or similar
Traceback (most recent call last):
  File "E:\Upwork\2020\gmail_app\gmail_app\env\lib\site-packages\sqlalchemy\pool\base.py", line 670, in _finalize_fairy
    fairy._reset(pool)
  File "E:\Upwork\2020\gmail_app\gmail_app\env\lib\site-packages\sqlalchemy\pool\base.py", line 875, in _reset
    pool._dialect.do_rollback(self)
  File "E:\Upwork\2020\gmail_app\gmail_app\env\lib\site-packages\sqlalchemy\engine\default.py", line 631, in do_rollback
    dbapi_connection.rollback()
sqlite3.ProgrammingError: SQLite objects created in a thread can only be used in that same thread. The object was created in thread id 11424 and this is thread id 3080.
2021-04-11 22:20:21,384 Exception closing connection <sqlite3.Connection object at 0x000001F35C48D110>
Traceback (most recent call last):
  File "E:\Upwork\2020\gmail_app\gmail_app\env\lib\site-packages\sqlalchemy\pool\base.py", line 670, in _finalize_fairy
    fairy._reset(pool)
  File "E:\Upwork\2020\gmail_app\gmail_app\env\lib\site-packages\sqlalchemy\pool\base.py", line 875, in _reset
    pool._dialect.do_rollback(self)
  File "E:\Upwork\2020\gmail_app\gmail_app\env\lib\site-packages\sqlalchemy\engine\default.py", line 631, in do_rollback
    dbapi_connection.rollback()
sqlite3.ProgrammingError: SQLite objects created in a thread can only be used in that same thread. The object was created in thread id 11424 and this is thread id 3080.

During handling of the above exception, another exception occurred:

Traceback (most recent call last):
  File "E:\Upwork\2020\gmail_app\gmail_app\env\lib\site-packages\sqlalchemy\pool\base.py", line 238, in _close_connection
    self._dialect.do_close(connection)
  File "E:\Upwork\2020\gmail_app\gmail_app\env\lib\site-packages\sqlalchemy\engine\default.py", line 637, in do_close
    dbapi_connection.close()
sqlite3.ProgrammingError: SQLite objects created in a thread can only be used in that same thread. The object was created in thread id 11424 and this is thread id 3080.
2021-04-11 22:20:34,036 Error at downloading email - fasteners360@gmail.com - Error connecting to SOCKS5 proxy 81.28.96.172:60742: [WinError 10061] No connection could be made because the target machine actively refused it
2021-04-11 22:20:55,284 Exception during reset or similar
Traceback (most recent call last):
  File "E:\Upwork\2020\gmail_app\gmail_app\env\lib\site-packages\sqlalchemy\pool\base.py", line 670, in _finalize_fairy
    fairy._reset(pool)
  File "E:\Upwork\2020\gmail_app\gmail_app\env\lib\site-packages\sqlalchemy\pool\base.py", line 875, in _reset
    pool._dialect.do_rollback(self)
  File "E:\Upwork\2020\gmail_app\gmail_app\env\lib\site-packages\sqlalchemy\engine\default.py", line 631, in do_rollback
    dbapi_connection.rollback()
sqlite3.ProgrammingError: SQLite objects created in a thread can only be used in that same thread. The object was created in thread id 3412 and this is thread id 8620.
2021-04-11 22:20:55,285 Exception closing connection <sqlite3.Connection object at 0x000002009144D110>
Traceback (most recent call last):
  File "E:\Upwork\2020\gmail_app\gmail_app\env\lib\site-packages\sqlalchemy\pool\base.py", line 670, in _finalize_fairy
    fairy._reset(pool)
  File "E:\Upwork\2020\gmail_app\gmail_app\env\lib\site-packages\sqlalchemy\pool\base.py", line 875, in _reset
    pool._dialect.do_rollback(self)
  File "E:\Upwork\2020\gmail_app\gmail_app\env\lib\site-packages\sqlalchemy\engine\default.py", line 631, in do_rollback
    dbapi_connection.rollback()
sqlite3.ProgrammingError: SQLite objects created in a thread can only be used in that same thread. The object was created in thread id 3412 and this is thread id 8620.

During handling of the above exception, another exception occurred:

Traceback (most recent call last):
  File "E:\Upwork\2020\gmail_app\gmail_app\env\lib\site-packages\sqlalchemy\pool\base.py", line 238, in _close_connection
    self._dialect.do_close(connection)
  File "E:\Upwork\2020\gmail_app\gmail_app\env\lib\site-packages\sqlalchemy\engine\default.py", line 637, in do_close
    dbapi_connection.close()
sqlite3.ProgrammingError: SQLite objects created in a thread can only be used in that same thread. The object was created in thread id 3412 and this is thread id 8620.
2021-04-11 22:24:52,531 Exception during reset or similar
Traceback (most recent call last):
  File "E:\Upwork\2020\gmail_app\gmail_app\env\lib\site-packages\sqlalchemy\pool\base.py", line 670, in _finalize_fairy
    fairy._reset(pool)
  File "E:\Upwork\2020\gmail_app\gmail_app\env\lib\site-packages\sqlalchemy\pool\base.py", line 875, in _reset
    pool._dialect.do_rollback(self)
  File "E:\Upwork\2020\gmail_app\gmail_app\env\lib\site-packages\sqlalchemy\engine\default.py", line 631, in do_rollback
    dbapi_connection.rollback()
sqlite3.ProgrammingError: SQLite objects created in a thread can only be used in that same thread. The object was created in thread id 3412 and this is thread id 8620.
2021-04-11 22:24:52,531 Exception closing connection <sqlite3.Connection object at 0x00000200913D5D50>
Traceback (most recent call last):
  File "E:\Upwork\2020\gmail_app\gmail_app\env\lib\site-packages\sqlalchemy\pool\base.py", line 670, in _finalize_fairy
    fairy._reset(pool)
  File "E:\Upwork\2020\gmail_app\gmail_app\env\lib\site-packages\sqlalchemy\pool\base.py", line 875, in _reset
    pool._dialect.do_rollback(self)
  File "E:\Upwork\2020\gmail_app\gmail_app\env\lib\site-packages\sqlalchemy\engine\default.py", line 631, in do_rollback
    dbapi_connection.rollback()
sqlite3.ProgrammingError: SQLite objects created in a thread can only be used in that same thread. The object was created in thread id 3412 and this is thread id 8620.

During handling of the above exception, another exception occurred:

Traceback (most recent call last):
  File "E:\Upwork\2020\gmail_app\gmail_app\env\lib\site-packages\sqlalchemy\pool\base.py", line 238, in _close_connection
    self._dialect.do_close(connection)
  File "E:\Upwork\2020\gmail_app\gmail_app\env\lib\site-packages\sqlalchemy\engine\default.py", line 637, in do_close
    dbapi_connection.close()
sqlite3.ProgrammingError: SQLite objects created in a thread can only be used in that same thread. The object was created in thread id 3412 and this is thread id 8620.
2021-04-11 22:25:07,622 Error at downloading email - fasteners360@gmail.com - Error connecting to SOCKS5 proxy 81.28.96.172:60742: [WinError 10061] No connection could be made because the target machine actively refused it
2021-04-11 22:25:28,026 Exception during reset or similar
Traceback (most recent call last):
  File "E:\Upwork\2020\gmail_app\gmail_app\env\lib\site-packages\sqlalchemy\pool\base.py", line 670, in _finalize_fairy
    fairy._reset(pool)
  File "E:\Upwork\2020\gmail_app\gmail_app\env\lib\site-packages\sqlalchemy\pool\base.py", line 875, in _reset
    pool._dialect.do_rollback(self)
  File "E:\Upwork\2020\gmail_app\gmail_app\env\lib\site-packages\sqlalchemy\engine\default.py", line 631, in do_rollback
    dbapi_connection.rollback()
sqlite3.ProgrammingError: SQLite objects created in a thread can only be used in that same thread. The object was created in thread id 5724 and this is thread id 9324.
2021-04-11 22:25:28,028 Exception closing connection <sqlite3.Connection object at 0x00000266DCB7E110>
Traceback (most recent call last):
  File "E:\Upwork\2020\gmail_app\gmail_app\env\lib\site-packages\sqlalchemy\pool\base.py", line 670, in _finalize_fairy
    fairy._reset(pool)
  File "E:\Upwork\2020\gmail_app\gmail_app\env\lib\site-packages\sqlalchemy\pool\base.py", line 875, in _reset
    pool._dialect.do_rollback(self)
  File "E:\Upwork\2020\gmail_app\gmail_app\env\lib\site-packages\sqlalchemy\engine\default.py", line 631, in do_rollback
    dbapi_connection.rollback()
sqlite3.ProgrammingError: SQLite objects created in a thread can only be used in that same thread. The object was created in thread id 5724 and this is thread id 9324.

During handling of the above exception, another exception occurred:

Traceback (most recent call last):
  File "E:\Upwork\2020\gmail_app\gmail_app\env\lib\site-packages\sqlalchemy\pool\base.py", line 238, in _close_connection
    self._dialect.do_close(connection)
  File "E:\Upwork\2020\gmail_app\gmail_app\env\lib\site-packages\sqlalchemy\engine\default.py", line 637, in do_close
    dbapi_connection.close()
sqlite3.ProgrammingError: SQLite objects created in a thread can only be used in that same thread. The object was created in thread id 5724 and this is thread id 9324.
2021-04-11 22:34:41,445 Exception during reset or similar
Traceback (most recent call last):
  File "E:\Upwork\2020\gmail_app\gmail_app\env\lib\site-packages\sqlalchemy\pool\base.py", line 670, in _finalize_fairy
    fairy._reset(pool)
  File "E:\Upwork\2020\gmail_app\gmail_app\env\lib\site-packages\sqlalchemy\pool\base.py", line 875, in _reset
    pool._dialect.do_rollback(self)
  File "E:\Upwork\2020\gmail_app\gmail_app\env\lib\site-packages\sqlalchemy\engine\default.py", line 631, in do_rollback
    dbapi_connection.rollback()
sqlite3.ProgrammingError: SQLite objects created in a thread can only be used in that same thread. The object was created in thread id 5724 and this is thread id 9324.
2021-04-11 22:34:41,446 Exception closing connection <sqlite3.Connection object at 0x00000266DB9A7D50>
Traceback (most recent call last):
  File "E:\Upwork\2020\gmail_app\gmail_app\env\lib\site-packages\sqlalchemy\pool\base.py", line 670, in _finalize_fairy
    fairy._reset(pool)
  File "E:\Upwork\2020\gmail_app\gmail_app\env\lib\site-packages\sqlalchemy\pool\base.py", line 875, in _reset
    pool._dialect.do_rollback(self)
  File "E:\Upwork\2020\gmail_app\gmail_app\env\lib\site-packages\sqlalchemy\engine\default.py", line 631, in do_rollback
    dbapi_connection.rollback()
sqlite3.ProgrammingError: SQLite objects created in a thread can only be used in that same thread. The object was created in thread id 5724 and this is thread id 9324.

During handling of the above exception, another exception occurred:

Traceback (most recent call last):
  File "E:\Upwork\2020\gmail_app\gmail_app\env\lib\site-packages\sqlalchemy\pool\base.py", line 238, in _close_connection
    self._dialect.do_close(connection)
  File "E:\Upwork\2020\gmail_app\gmail_app\env\lib\site-packages\sqlalchemy\engine\default.py", line 637, in do_close
    dbapi_connection.close()
sqlite3.ProgrammingError: SQLite objects created in a thread can only be used in that same thread. The object was created in thread id 5724 and this is thread id 9324.
2021-04-11 22:35:01,100 Error at downloading email - fasteners360@gmail.com - Error connecting to SOCKS5 proxy 81.28.96.172:60742: [WinError 10061] No connection could be made because the target machine actively refused it
2021-04-11 22:35:16,368 Exception during reset or similar
Traceback (most recent call last):
  File "E:\Upwork\2020\gmail_app\gmail_app\env\lib\site-packages\sqlalchemy\pool\base.py", line 670, in _finalize_fairy
    fairy._reset(pool)
  File "E:\Upwork\2020\gmail_app\gmail_app\env\lib\site-packages\sqlalchemy\pool\base.py", line 875, in _reset
    pool._dialect.do_rollback(self)
  File "E:\Upwork\2020\gmail_app\gmail_app\env\lib\site-packages\sqlalchemy\engine\default.py", line 631, in do_rollback
    dbapi_connection.rollback()
sqlite3.ProgrammingError: SQLite objects created in a thread can only be used in that same thread. The object was created in thread id 13460 and this is thread id 5572.
2021-04-11 22:35:16,593 Exception closing connection <sqlite3.Connection object at 0x0000022B21FCE110>
Traceback (most recent call last):
  File "E:\Upwork\2020\gmail_app\gmail_app\env\lib\site-packages\sqlalchemy\pool\base.py", line 670, in _finalize_fairy
    fairy._reset(pool)
  File "E:\Upwork\2020\gmail_app\gmail_app\env\lib\site-packages\sqlalchemy\pool\base.py", line 875, in _reset
    pool._dialect.do_rollback(self)
  File "E:\Upwork\2020\gmail_app\gmail_app\env\lib\site-packages\sqlalchemy\engine\default.py", line 631, in do_rollback
    dbapi_connection.rollback()
sqlite3.ProgrammingError: SQLite objects created in a thread can only be used in that same thread. The object was created in thread id 13460 and this is thread id 5572.

During handling of the above exception, another exception occurred:

Traceback (most recent call last):
  File "E:\Upwork\2020\gmail_app\gmail_app\env\lib\site-packages\sqlalchemy\pool\base.py", line 238, in _close_connection
    self._dialect.do_close(connection)
  File "E:\Upwork\2020\gmail_app\gmail_app\env\lib\site-packages\sqlalchemy\engine\default.py", line 637, in do_close
    dbapi_connection.close()
sqlite3.ProgrammingError: SQLite objects created in a thread can only be used in that same thread. The object was created in thread id 13460 and this is thread id 5572.
2021-04-11 22:38:03,764 Exception during reset or similar
Traceback (most recent call last):
  File "E:\Upwork\2020\gmail_app\gmail_app\env\lib\site-packages\sqlalchemy\pool\base.py", line 670, in _finalize_fairy
    fairy._reset(pool)
  File "E:\Upwork\2020\gmail_app\gmail_app\env\lib\site-packages\sqlalchemy\pool\base.py", line 875, in _reset
    pool._dialect.do_rollback(self)
  File "E:\Upwork\2020\gmail_app\gmail_app\env\lib\site-packages\sqlalchemy\engine\default.py", line 631, in do_rollback
    dbapi_connection.rollback()
sqlite3.ProgrammingError: SQLite objects created in a thread can only be used in that same thread. The object was created in thread id 13460 and this is thread id 5572.
2021-04-11 22:38:03,764 Exception closing connection <sqlite3.Connection object at 0x0000022B21F55B90>
Traceback (most recent call last):
  File "E:\Upwork\2020\gmail_app\gmail_app\env\lib\site-packages\sqlalchemy\pool\base.py", line 670, in _finalize_fairy
    fairy._reset(pool)
  File "E:\Upwork\2020\gmail_app\gmail_app\env\lib\site-packages\sqlalchemy\pool\base.py", line 875, in _reset
    pool._dialect.do_rollback(self)
  File "E:\Upwork\2020\gmail_app\gmail_app\env\lib\site-packages\sqlalchemy\engine\default.py", line 631, in do_rollback
    dbapi_connection.rollback()
sqlite3.ProgrammingError: SQLite objects created in a thread can only be used in that same thread. The object was created in thread id 13460 and this is thread id 5572.

During handling of the above exception, another exception occurred:

Traceback (most recent call last):
  File "E:\Upwork\2020\gmail_app\gmail_app\env\lib\site-packages\sqlalchemy\pool\base.py", line 238, in _close_connection
    self._dialect.do_close(connection)
  File "E:\Upwork\2020\gmail_app\gmail_app\env\lib\site-packages\sqlalchemy\engine\default.py", line 637, in do_close
    dbapi_connection.close()
sqlite3.ProgrammingError: SQLite objects created in a thread can only be used in that same thread. The object was created in thread id 13460 and this is thread id 5572.
2021-04-11 22:46:24,481 Error at downloading email - fasteners360@gmail.com - Error connecting to SOCKS5 proxy 81.28.96.172:60742: [WinError 10061] No connection could be made because the target machine actively refused it
2021-04-11 22:46:50,060 Exception during reset or similar
Traceback (most recent call last):
  File "E:\Upwork\2020\gmail_app\gmail_app\env\lib\site-packages\sqlalchemy\pool\base.py", line 670, in _finalize_fairy
    fairy._reset(pool)
  File "E:\Upwork\2020\gmail_app\gmail_app\env\lib\site-packages\sqlalchemy\pool\base.py", line 875, in _reset
    pool._dialect.do_rollback(self)
  File "E:\Upwork\2020\gmail_app\gmail_app\env\lib\site-packages\sqlalchemy\engine\default.py", line 631, in do_rollback
    dbapi_connection.rollback()
sqlite3.ProgrammingError: SQLite objects created in a thread can only be used in that same thread. The object was created in thread id 7676 and this is thread id 7960.
2021-04-11 22:46:50,062 Exception closing connection <sqlite3.Connection object at 0x0000026B5782F110>
Traceback (most recent call last):
  File "E:\Upwork\2020\gmail_app\gmail_app\env\lib\site-packages\sqlalchemy\pool\base.py", line 670, in _finalize_fairy
    fairy._reset(pool)
  File "E:\Upwork\2020\gmail_app\gmail_app\env\lib\site-packages\sqlalchemy\pool\base.py", line 875, in _reset
    pool._dialect.do_rollback(self)
  File "E:\Upwork\2020\gmail_app\gmail_app\env\lib\site-packages\sqlalchemy\engine\default.py", line 631, in do_rollback
    dbapi_connection.rollback()
sqlite3.ProgrammingError: SQLite objects created in a thread can only be used in that same thread. The object was created in thread id 7676 and this is thread id 7960.

During handling of the above exception, another exception occurred:

Traceback (most recent call last):
  File "E:\Upwork\2020\gmail_app\gmail_app\env\lib\site-packages\sqlalchemy\pool\base.py", line 238, in _close_connection
    self._dialect.do_close(connection)
  File "E:\Upwork\2020\gmail_app\gmail_app\env\lib\site-packages\sqlalchemy\engine\default.py", line 637, in do_close
    dbapi_connection.close()
sqlite3.ProgrammingError: SQLite objects created in a thread can only be used in that same thread. The object was created in thread id 7676 and this is thread id 7960.
2021-04-11 22:57:43,341 Exception during reset or similar
Traceback (most recent call last):
  File "E:\Upwork\2020\gmail_app\gmail_app\env\lib\site-packages\sqlalchemy\pool\base.py", line 670, in _finalize_fairy
    fairy._reset(pool)
  File "E:\Upwork\2020\gmail_app\gmail_app\env\lib\site-packages\sqlalchemy\pool\base.py", line 875, in _reset
    pool._dialect.do_rollback(self)
  File "E:\Upwork\2020\gmail_app\gmail_app\env\lib\site-packages\sqlalchemy\engine\default.py", line 631, in do_rollback
    dbapi_connection.rollback()
sqlite3.ProgrammingError: SQLite objects created in a thread can only be used in that same thread. The object was created in thread id 7676 and this is thread id 7960.
2021-04-11 22:57:43,342 Exception closing connection <sqlite3.Connection object at 0x0000026B577B8D50>
Traceback (most recent call last):
  File "E:\Upwork\2020\gmail_app\gmail_app\env\lib\site-packages\sqlalchemy\pool\base.py", line 670, in _finalize_fairy
    fairy._reset(pool)
  File "E:\Upwork\2020\gmail_app\gmail_app\env\lib\site-packages\sqlalchemy\pool\base.py", line 875, in _reset
    pool._dialect.do_rollback(self)
  File "E:\Upwork\2020\gmail_app\gmail_app\env\lib\site-packages\sqlalchemy\engine\default.py", line 631, in do_rollback
    dbapi_connection.rollback()
sqlite3.ProgrammingError: SQLite objects created in a thread can only be used in that same thread. The object was created in thread id 7676 and this is thread id 7960.

During handling of the above exception, another exception occurred:

Traceback (most recent call last):
  File "E:\Upwork\2020\gmail_app\gmail_app\env\lib\site-packages\sqlalchemy\pool\base.py", line 238, in _close_connection
    self._dialect.do_close(connection)
  File "E:\Upwork\2020\gmail_app\gmail_app\env\lib\site-packages\sqlalchemy\engine\default.py", line 637, in do_close
    dbapi_connection.close()
sqlite3.ProgrammingError: SQLite objects created in a thread can only be used in that same thread. The object was created in thread id 7676 and this is thread id 7960.
2021-04-11 22:58:21,793 Error at downloading email - fasteners360@gmail.com - Error connecting to SOCKS5 proxy 81.28.96.172:60742: [WinError 10061] No connection could be made because the target machine actively refused it
2021-04-11 22:58:38,152 Exception during reset or similar
Traceback (most recent call last):
  File "E:\Upwork\2020\gmail_app\gmail_app\env\lib\site-packages\sqlalchemy\pool\base.py", line 670, in _finalize_fairy
    fairy._reset(pool)
  File "E:\Upwork\2020\gmail_app\gmail_app\env\lib\site-packages\sqlalchemy\pool\base.py", line 875, in _reset
    pool._dialect.do_rollback(self)
  File "E:\Upwork\2020\gmail_app\gmail_app\env\lib\site-packages\sqlalchemy\engine\default.py", line 631, in do_rollback
    dbapi_connection.rollback()
sqlite3.ProgrammingError: SQLite objects created in a thread can only be used in that same thread. The object was created in thread id 9260 and this is thread id 12688.
2021-04-11 22:58:38,153 Exception closing connection <sqlite3.Connection object at 0x00000284B4D2F110>
Traceback (most recent call last):
  File "E:\Upwork\2020\gmail_app\gmail_app\env\lib\site-packages\sqlalchemy\pool\base.py", line 670, in _finalize_fairy
    fairy._reset(pool)
  File "E:\Upwork\2020\gmail_app\gmail_app\env\lib\site-packages\sqlalchemy\pool\base.py", line 875, in _reset
    pool._dialect.do_rollback(self)
  File "E:\Upwork\2020\gmail_app\gmail_app\env\lib\site-packages\sqlalchemy\engine\default.py", line 631, in do_rollback
    dbapi_connection.rollback()
sqlite3.ProgrammingError: SQLite objects created in a thread can only be used in that same thread. The object was created in thread id 9260 and this is thread id 12688.

During handling of the above exception, another exception occurred:

Traceback (most recent call last):
  File "E:\Upwork\2020\gmail_app\gmail_app\env\lib\site-packages\sqlalchemy\pool\base.py", line 238, in _close_connection
    self._dialect.do_close(connection)
  File "E:\Upwork\2020\gmail_app\gmail_app\env\lib\site-packages\sqlalchemy\engine\default.py", line 637, in do_close
    dbapi_connection.close()
sqlite3.ProgrammingError: SQLite objects created in a thread can only be used in that same thread. The object was created in thread id 9260 and this is thread id 12688.
2021-04-11 23:06:22,897 Exception during reset or similar
Traceback (most recent call last):
  File "E:\Upwork\2020\gmail_app\gmail_app\env\lib\site-packages\sqlalchemy\pool\base.py", line 670, in _finalize_fairy
    fairy._reset(pool)
  File "E:\Upwork\2020\gmail_app\gmail_app\env\lib\site-packages\sqlalchemy\pool\base.py", line 875, in _reset
    pool._dialect.do_rollback(self)
  File "E:\Upwork\2020\gmail_app\gmail_app\env\lib\site-packages\sqlalchemy\engine\default.py", line 631, in do_rollback
    dbapi_connection.rollback()
sqlite3.ProgrammingError: SQLite objects created in a thread can only be used in that same thread. The object was created in thread id 9260 and this is thread id 12688.
2021-04-11 23:06:22,898 Exception closing connection <sqlite3.Connection object at 0x00000284B4CB5D50>
Traceback (most recent call last):
  File "E:\Upwork\2020\gmail_app\gmail_app\env\lib\site-packages\sqlalchemy\pool\base.py", line 670, in _finalize_fairy
    fairy._reset(pool)
  File "E:\Upwork\2020\gmail_app\gmail_app\env\lib\site-packages\sqlalchemy\pool\base.py", line 875, in _reset
    pool._dialect.do_rollback(self)
  File "E:\Upwork\2020\gmail_app\gmail_app\env\lib\site-packages\sqlalchemy\engine\default.py", line 631, in do_rollback
    dbapi_connection.rollback()
sqlite3.ProgrammingError: SQLite objects created in a thread can only be used in that same thread. The object was created in thread id 9260 and this is thread id 12688.

During handling of the above exception, another exception occurred:

Traceback (most recent call last):
  File "E:\Upwork\2020\gmail_app\gmail_app\env\lib\site-packages\sqlalchemy\pool\base.py", line 238, in _close_connection
    self._dialect.do_close(connection)
  File "E:\Upwork\2020\gmail_app\gmail_app\env\lib\site-packages\sqlalchemy\engine\default.py", line 637, in do_close
    dbapi_connection.close()
sqlite3.ProgrammingError: SQLite objects created in a thread can only be used in that same thread. The object was created in thread id 9260 and this is thread id 12688.
2021-04-11 23:06:35,163 Error at downloading email - fasteners360@gmail.com - Error connecting to SOCKS5 proxy 81.28.96.172:60742: [WinError 10061] No connection could be made because the target machine actively refused it
2021-04-11 23:07:03,384 Exception during reset or similar
Traceback (most recent call last):
  File "E:\Upwork\2020\gmail_app\gmail_app\env\lib\site-packages\sqlalchemy\pool\base.py", line 670, in _finalize_fairy
    fairy._reset(pool)
  File "E:\Upwork\2020\gmail_app\gmail_app\env\lib\site-packages\sqlalchemy\pool\base.py", line 875, in _reset
    pool._dialect.do_rollback(self)
  File "E:\Upwork\2020\gmail_app\gmail_app\env\lib\site-packages\sqlalchemy\engine\default.py", line 631, in do_rollback
    dbapi_connection.rollback()
sqlite3.ProgrammingError: SQLite objects created in a thread can only be used in that same thread. The object was created in thread id 11484 and this is thread id 14476.
2021-04-11 23:07:03,386 Exception closing connection <sqlite3.Connection object at 0x0000022545BDE110>
Traceback (most recent call last):
  File "E:\Upwork\2020\gmail_app\gmail_app\env\lib\site-packages\sqlalchemy\pool\base.py", line 670, in _finalize_fairy
    fairy._reset(pool)
  File "E:\Upwork\2020\gmail_app\gmail_app\env\lib\site-packages\sqlalchemy\pool\base.py", line 875, in _reset
    pool._dialect.do_rollback(self)
  File "E:\Upwork\2020\gmail_app\gmail_app\env\lib\site-packages\sqlalchemy\engine\default.py", line 631, in do_rollback
    dbapi_connection.rollback()
sqlite3.ProgrammingError: SQLite objects created in a thread can only be used in that same thread. The object was created in thread id 11484 and this is thread id 14476.

During handling of the above exception, another exception occurred:

Traceback (most recent call last):
  File "E:\Upwork\2020\gmail_app\gmail_app\env\lib\site-packages\sqlalchemy\pool\base.py", line 238, in _close_connection
    self._dialect.do_close(connection)
  File "E:\Upwork\2020\gmail_app\gmail_app\env\lib\site-packages\sqlalchemy\engine\default.py", line 637, in do_close
    dbapi_connection.close()
sqlite3.ProgrammingError: SQLite objects created in a thread can only be used in that same thread. The object was created in thread id 11484 and this is thread id 14476.
2021-04-11 23:08:40,231 Exception during reset or similar
Traceback (most recent call last):
  File "E:\Upwork\2020\gmail_app\gmail_app\env\lib\site-packages\sqlalchemy\pool\base.py", line 670, in _finalize_fairy
    fairy._reset(pool)
  File "E:\Upwork\2020\gmail_app\gmail_app\env\lib\site-packages\sqlalchemy\pool\base.py", line 875, in _reset
    pool._dialect.do_rollback(self)
  File "E:\Upwork\2020\gmail_app\gmail_app\env\lib\site-packages\sqlalchemy\engine\default.py", line 631, in do_rollback
    dbapi_connection.rollback()
sqlite3.ProgrammingError: SQLite objects created in a thread can only be used in that same thread. The object was created in thread id 11484 and this is thread id 14476.
2021-04-11 23:08:40,232 Exception closing connection <sqlite3.Connection object at 0x0000022545B67D50>
Traceback (most recent call last):
  File "E:\Upwork\2020\gmail_app\gmail_app\env\lib\site-packages\sqlalchemy\pool\base.py", line 670, in _finalize_fairy
    fairy._reset(pool)
  File "E:\Upwork\2020\gmail_app\gmail_app\env\lib\site-packages\sqlalchemy\pool\base.py", line 875, in _reset
    pool._dialect.do_rollback(self)
  File "E:\Upwork\2020\gmail_app\gmail_app\env\lib\site-packages\sqlalchemy\engine\default.py", line 631, in do_rollback
    dbapi_connection.rollback()
sqlite3.ProgrammingError: SQLite objects created in a thread can only be used in that same thread. The object was created in thread id 11484 and this is thread id 14476.

During handling of the above exception, another exception occurred:

Traceback (most recent call last):
  File "E:\Upwork\2020\gmail_app\gmail_app\env\lib\site-packages\sqlalchemy\pool\base.py", line 238, in _close_connection
    self._dialect.do_close(connection)
  File "E:\Upwork\2020\gmail_app\gmail_app\env\lib\site-packages\sqlalchemy\engine\default.py", line 637, in do_close
    dbapi_connection.close()
sqlite3.ProgrammingError: SQLite objects created in a thread can only be used in that same thread. The object was created in thread id 11484 and this is thread id 14476.
2021-04-11 23:14:58,697 Found no block messages : Anastasia.Jimenez1990@gmail.com 2021-04-11 23:14:58.697142
2021-04-11 23:15:13,283 Found no block messages : Anastasia.Jimenez1990@gmail.com 2021-04-11 23:15:13.283142
2021-04-11 23:15:33,281 Exception during reset or similar
Traceback (most recent call last):
  File "E:\Upwork\2020\gmail_app\gmail_app\env\lib\site-packages\sqlalchemy\pool\base.py", line 670, in _finalize_fairy
    fairy._reset(pool)
  File "E:\Upwork\2020\gmail_app\gmail_app\env\lib\site-packages\sqlalchemy\pool\base.py", line 875, in _reset
    pool._dialect.do_rollback(self)
  File "E:\Upwork\2020\gmail_app\gmail_app\env\lib\site-packages\sqlalchemy\engine\default.py", line 631, in do_rollback
    dbapi_connection.rollback()
sqlite3.ProgrammingError: SQLite objects created in a thread can only be used in that same thread. The object was created in thread id 8664 and this is thread id 1496.
2021-04-11 23:15:33,283 Exception closing connection <sqlite3.Connection object at 0x000001FEE1F66D50>
Traceback (most recent call last):
  File "E:\Upwork\2020\gmail_app\gmail_app\env\lib\site-packages\sqlalchemy\pool\base.py", line 670, in _finalize_fairy
    fairy._reset(pool)
  File "E:\Upwork\2020\gmail_app\gmail_app\env\lib\site-packages\sqlalchemy\pool\base.py", line 875, in _reset
    pool._dialect.do_rollback(self)
  File "E:\Upwork\2020\gmail_app\gmail_app\env\lib\site-packages\sqlalchemy\engine\default.py", line 631, in do_rollback
    dbapi_connection.rollback()
sqlite3.ProgrammingError: SQLite objects created in a thread can only be used in that same thread. The object was created in thread id 8664 and this is thread id 1496.

During handling of the above exception, another exception occurred:

Traceback (most recent call last):
  File "E:\Upwork\2020\gmail_app\gmail_app\env\lib\site-packages\sqlalchemy\pool\base.py", line 238, in _close_connection
    self._dialect.do_close(connection)
  File "E:\Upwork\2020\gmail_app\gmail_app\env\lib\site-packages\sqlalchemy\engine\default.py", line 637, in do_close
    dbapi_connection.close()
sqlite3.ProgrammingError: SQLite objects created in a thread can only be used in that same thread. The object was created in thread id 8664 and this is thread id 1496.
2021-04-11 23:15:33,285 Exception during reset or similar
Traceback (most recent call last):
  File "E:\Upwork\2020\gmail_app\gmail_app\env\lib\site-packages\sqlalchemy\pool\base.py", line 670, in _finalize_fairy
    fairy._reset(pool)
  File "E:\Upwork\2020\gmail_app\gmail_app\env\lib\site-packages\sqlalchemy\pool\base.py", line 875, in _reset
    pool._dialect.do_rollback(self)
  File "E:\Upwork\2020\gmail_app\gmail_app\env\lib\site-packages\sqlalchemy\engine\default.py", line 631, in do_rollback
    dbapi_connection.rollback()
sqlite3.ProgrammingError: SQLite objects created in a thread can only be used in that same thread. The object was created in thread id 8664 and this is thread id 1496.
2021-04-11 23:15:33,285 Exception closing connection <sqlite3.Connection object at 0x000001FEE1FE0110>
Traceback (most recent call last):
  File "E:\Upwork\2020\gmail_app\gmail_app\env\lib\site-packages\sqlalchemy\pool\base.py", line 670, in _finalize_fairy
    fairy._reset(pool)
  File "E:\Upwork\2020\gmail_app\gmail_app\env\lib\site-packages\sqlalchemy\pool\base.py", line 875, in _reset
    pool._dialect.do_rollback(self)
  File "E:\Upwork\2020\gmail_app\gmail_app\env\lib\site-packages\sqlalchemy\engine\default.py", line 631, in do_rollback
    dbapi_connection.rollback()
sqlite3.ProgrammingError: SQLite objects created in a thread can only be used in that same thread. The object was created in thread id 8664 and this is thread id 1496.

During handling of the above exception, another exception occurred:

Traceback (most recent call last):
  File "E:\Upwork\2020\gmail_app\gmail_app\env\lib\site-packages\sqlalchemy\pool\base.py", line 238, in _close_connection
    self._dialect.do_close(connection)
  File "E:\Upwork\2020\gmail_app\gmail_app\env\lib\site-packages\sqlalchemy\engine\default.py", line 637, in do_close
    dbapi_connection.close()
sqlite3.ProgrammingError: SQLite objects created in a thread can only be used in that same thread. The object was created in thread id 8664 and this is thread id 1496.
